<?xml version="1.0" ?>
<!-- =================================================================================== -->
<!-- |    This document was autogenerated by xacro from single_rrbot.urdf.xacro        | -->
<!-- |    EDITING THIS FILE BY HAND IS NOT RECOMMENDED                                 | -->
<!-- =================================================================================== -->
<robot name="single_rrbot" xmlns:xacro="http://www.ros.org/wiki/xacro">
  <!-- Import your models -->
  <material name="RRBOT/black">
    <color rgba="0.0 0.0 0.0 1.0"/>
  </material>
  <material name="RRBOT/blue">
    <color rgba="0.0 0.0 0.8 1.0"/>
  </material>
  <material name="RRBOT/green">
    <color rgba="0.0 0.8 0.0 1.0"/>
  </material>
  <material name="RRBOT/grey">
    <color rgba="0.2 0.2 0.2 1.0"/>
  </material>
  <material name="RRBOT/orange">
    <color rgba="1.0 0.423529411765 0.0392156862745 1.0"/>
  </material>
  <material name="RRBOT/brown">
    <color rgba="0.870588235294 0.811764705882 0.764705882353 1.0"/>
  </material>
  <material name="RRBOT/red">
    <color rgba="0.8 0.0 0.0 1.0"/>
  </material>
  <material name="RRBOT/white">
    <color rgba="1.0 1.0 1.0 1.0"/>
  </material>
  <!-- Build your comprehensive robot -->
  <link name="world"/>
  <gazebo reference="world">
    <static>true</static>
  </gazebo>
  <joint name="single_rrbot_fixed" type="fixed">
    <origin rpy="0 0 0" xyz="0 0 0"/>
    <parent link="world"/>
    <child link="single_rrbot_link1"/>
  </joint>
  <link name="single_rrbot_link1">
    <collision>
      <origin rpy="0 0 0" xyz="0 0 1.0"/>
      <geometry>
        <box size="0.1 0.1 2"/>
      </geometry>
    </collision>
    <visual>
      <origin rpy="0 0 0" xyz="0 0 1.0"/>
      <geometry>
        <box size="0.1 0.1 2"/>
      </geometry>
      <material name="RRBOT/orange"/>
    </visual>
    <inertial>
      <origin rpy="0 0 0" xyz="0 0 1.0"/>
      <mass value="1"/>
      <inertia ixx="1.0" ixy="0.0" ixz="0.0" iyy="1.0" iyz="0.0" izz="1.0"/>
    </inertial>
  </link>
  <joint name="single_rrbot_joint1" type="continuous">
    <parent link="single_rrbot_link1"/>
    <child link="single_rrbot_link2"/>
    <origin rpy="0 0 0" xyz="0 0.1 1.95"/>
    <axis xyz="0 1 0"/>
    <dynamics damping="0.7"/>
  </joint>
  <link name="single_rrbot_link2">
    <collision>
      <origin rpy="0 0 0" xyz="0 0 0.45"/>
      <geometry>
        <box size="0.1 0.1 1"/>
      </geometry>
    </collision>
    <visual>
      <origin rpy="0 0 0" xyz="0 0 0.45"/>
      <geometry>
        <box size="0.1 0.1 1"/>
      </geometry>
      <material name="RRBOT/black"/>
    </visual>
    <inertial>
      <origin rpy="0 0 0" xyz="0 0 0.45"/>
      <mass value="1"/>
      <inertia ixx="1.0" ixy="0.0" ixz="0.0" iyy="1.0" iyz="0.0" izz="1.0"/>
    </inertial>
  </link>
  <joint name="single_rrbot_joint2" type="continuous">
    <parent link="single_rrbot_link2"/>
    <child link="single_rrbot_link3"/>
    <origin rpy="0 0 0" xyz="0 0.1 0.9"/>
    <axis xyz="0 1 0"/>
    <dynamics damping="0.7"/>
  </joint>
  <link name="single_rrbot_link3">
    <collision>
      <origin rpy="0 0 0" xyz="0 0 0.45"/>
      <geometry>
        <box size="0.1 0.1 1"/>
      </geometry>
    </collision>
    <visual>
      <origin rpy="0 0 0" xyz="0 0 0.45"/>
      <geometry>
        <box size="0.1 0.1 1"/>
      </geometry>
      <material name="RRBOT/orange"/>
    </visual>
    <inertial>
      <origin rpy="0 0 0" xyz="0 0 0.45"/>
      <mass value="1"/>
      <inertia ixx="1.0" ixy="0.0" ixz="0.0" iyy="1.0" iyz="0.0" izz="1.0"/>
    </inertial>
  </link>
  <joint name="single_rrbot_hokuyo_joint" type="fixed">
    <axis xyz="0 1 0"/>
    <origin rpy="0 0 0" xyz="0 0 0.975"/>
    <parent link="single_rrbot_link3"/>
    <child link="single_rrbot_hokuyo_link"/>
  </joint>
  <link name="single_rrbot_hokuyo_link">
    <collision>
      <origin rpy="0 0 0" xyz="0 0 0"/>
      <geometry>
        <box size="0.1 0.1 0.1"/>
      </geometry>
    </collision>
    <visual>
      <origin rpy="0 0 0" xyz="0 0 0"/>
      <geometry>
        <box size="0.1 0.1 0.1"/>
      </geometry>
    </visual>
    <inertial>
      <mass value="1e-5"/>
      <origin rpy="0 0 0" xyz="0 0 0"/>
      <inertia ixx="1e-6" ixy="0" ixz="0" iyy="1e-6" iyz="0" izz="1e-6"/>
    </inertial>
  </link>
  <joint name="single_rrbot_camera_joint" type="fixed">
    <axis xyz="0 1 0"/>
    <origin rpy="0 0 0" xyz="0.05 0 0.9"/>
    <parent link="single_rrbot_link3"/>
    <child link="single_rrbot_camera_link"/>
  </joint>
  <link name="single_rrbot_camera_link">
    <collision>
      <origin rpy="0 0 0" xyz="0 0 0"/>
      <geometry>
        <box size="0.05 0.05 0.05"/>
      </geometry>
    </collision>
    <visual>
      <origin rpy="0 0 0" xyz="0 0 0"/>
      <geometry>
        <box size="0.05 0.05 0.05"/>
      </geometry>
      <material name="RRBOT/red"/>
    </visual>
    <inertial>
      <mass value="1e-5"/>
      <origin rpy="0 0 0" xyz="0 0 0"/>
      <inertia ixx="1e-6" ixy="0" ixz="0" iyy="1e-6" iyz="0" izz="1e-6"/>
    </inertial>
  </link>
  <transmission name="single_rrbot_tran1">
    <type>transmission_interface/SimpleTransmission</type>
    <joint name="single_rrbot_joint1">
      <hardwareInterface>PositionJointInterface</hardwareInterface>
    </joint>
    <actuator name="single_rrbot_motor1">
      <mechanicalReduction>1</mechanicalReduction>
    </actuator>
  </transmission>
  <transmission name="single_rrbot_tran2">
    <type>transmission_interface/SimpleTransmission</type>
    <joint name="single_rrbot_joint2">
      <hardwareInterface>PositionJointInterface</hardwareInterface>
    </joint>
    <actuator name="single_rrbot_motor2">
      <mechanicalReduction>1</mechanicalReduction>
    </actuator>
  </transmission>
  <gazebo>
    <plugin filename="librrbot_hw_sim_plugin.so" name="single_rrbot_hw_sim_plugin">
      <robotNamespace>single_rrbot</robotNamespace>
      <!-- add your custom sim behavior -->
      <robotSimType>rrbot_hw/DefaultRRBOTHWSim</robotSimType>
    </plugin>
  </gazebo>
  <gazebo reference="single_rrbot_link1">
    <material>Gazebo/Orange</material>
  </gazebo>
  <gazebo reference="single_rrbot_link2">
    <mu1>0.2</mu1>
    <mu2>0.2</mu2>
    <material>Gazebo/Black</material>
  </gazebo>
  <gazebo reference="single_rrbot_link3">
    <mu1>0.2</mu1>
    <mu2>0.2</mu2>
    <material>Gazebo/Orange</material>
  </gazebo>
  <gazebo reference="single_rrbot_camera_link">
    <mu1>0.2</mu1>
    <mu2>0.2</mu2>
    <material>Gazebo/Red</material>
  </gazebo>
  <gazebo reference="single_rrbot_hokuyo_link">
    <sensor name="head_hokuyo_sensor" type="gpu_ray">
      <pose>0 0 0 0 0 0</pose>
      <visualize>false</visualize>
      <update_rate>40</update_rate>
      <ray>
        <scan>
          <horizontal>
            <samples>720</samples>
            <resolution>1</resolution>
            <min_angle>-1.570796</min_angle>
            <max_angle>1.570796</max_angle>
          </horizontal>
        </scan>
        <range>
          <min>0.10</min>
          <max>30.0</max>
          <resolution>0.01</resolution>
        </range>
        <noise>
          <type>gaussian</type>
          <!-- Noise parameters based on published spec for Hokuyo laser
                 achieving "+-30mm" accuracy at range < 10m.  A mean of 0.0m and
                 stddev of 0.01m will put 99.7% of samples within 0.03m of the true
                 reading. -->
          <mean>0.0</mean>
          <stddev>0.01</stddev>
        </noise>
      </ray>
      <plugin filename="libgazebo_ros_gpu_laser.so" name="single_rrbot_gazebo_ros_head_hokuyo_controller">
        <!-- Publish within the robot namespace -->
        <robotNamespace>single_rrbot</robotNamespace>
        <topicName>laser/scan</topicName>
        <frameName>single_rrbot_hokuyo_link</frameName>
      </plugin>
    </sensor>
  </gazebo>
  <gazebo reference="single_rrbot_camera_link">
    <sensor name="camera1" type="camera">
      <update_rate>30.0</update_rate>
      <camera name="single_rrbot_head">
        <horizontal_fov>1.3962634</horizontal_fov>
        <image>
          <width>800</width>
          <height>800</height>
          <format>R8G8B8</format>
        </image>
        <clip>
          <near>0.02</near>
          <far>300</far>
        </clip>
        <noise>
          <type>gaussian</type>
          <!-- Noise is sampled independently per pixel on each frame.  
                 That pixel's noise value is added to each of its color
                 channels, which at that point lie in the range [0,1]. -->
          <mean>0.0</mean>
          <stddev>0.007</stddev>
        </noise>
      </camera>
      <plugin filename="libgazebo_ros_camera.so" name="single_rrbot_camera_controller">
        <alwaysOn>true</alwaysOn>
        <updateRate>0.0</updateRate>
        <robotNamespace>single_rrbot</robotNamespace>
        <cameraName>single_rrbot_camera1</cameraName>
        <imageTopicName>image_raw</imageTopicName>
        <cameraInfoTopicName>camera_info</cameraInfoTopicName>
        <frameName>single_rrbot_camera_link</frameName>
        <hackBaseline>0.07</hackBaseline>
        <distortionK1>0.0</distortionK1>
        <distortionK2>0.0</distortionK2>
        <distortionK3>0.0</distortionK3>
        <distortionT1>0.0</distortionT1>
        <distortionT2>0.0</distortionT2>
      </plugin>
    </sensor>
  </gazebo>
</robot>

